<sdf version='1.7'>
  <world name='default'>
    <light name='sun' type='directional'>
      <cast_shadows>1</cast_shadows>
      <pose>0 0 10 0 -0 0</pose>
      <diffuse>0.8 0.8 0.8 1</diffuse>
      <specular>0.2 0.2 0.2 1</specular>
      <attenuation>
        <range>1000</range>
        <constant>0.9</constant>
        <linear>0.01</linear>
        <quadratic>0.001</quadratic>
      </attenuation>
      <direction>-0.5 0.1 -0.9</direction>
      <spot>
        <inner_angle>0</inner_angle>
        <outer_angle>0</outer_angle>
        <falloff>0</falloff>
      </spot>
    </light>
    <model name='ground_plane'>
      <static>1</static>
      <link name='link'>
        <collision name='collision'>
          <geometry>
            <plane>
              <normal>0 0 1</normal>
              <size>100 100</size>
            </plane>
          </geometry>
          <surface>
            <friction>
              <ode>
                <mu>100</mu>
                <mu2>50</mu2>
              </ode>
              <torsional>
                <ode/>
              </torsional>
            </friction>
            <contact>
              <ode/>
            </contact>
            <bounce/>
          </surface>
          <max_contacts>10</max_contacts>
        </collision>
        <visual name='visual'>
          <cast_shadows>0</cast_shadows>
          <geometry>
            <plane>
              <normal>0 0 1</normal>
              <size>100 100</size>
            </plane>
          </geometry>
          <material>
            <script>
              <uri>file://media/materials/scripts/gazebo.material</uri>
              <name>Gazebo/Grey</name>
            </script>
          </material>
        </visual>
        <self_collide>0</self_collide>
        <enable_wind>0</enable_wind>
        <kinematic>0</kinematic>
      </link>
    </model>
    <gravity>0 0 -9.8</gravity>
    <magnetic_field>6e-06 2.3e-05 -4.2e-05</magnetic_field>
    <atmosphere type='adiabatic'/>
    <physics type='ode'>
      <max_step_size>0.001</max_step_size>
      <real_time_factor>1</real_time_factor>
      <real_time_update_rate>1000</real_time_update_rate>
    </physics>
    <scene>
      <ambient>0.4 0.4 0.4 1</ambient>
      <background>0.7 0.7 0.7 1</background>
      <shadows>1</shadows>
    </scene>
    <wind/>
    <spherical_coordinates>
      <surface_model>EARTH_WGS84</surface_model>
      <latitude_deg>0</latitude_deg>
      <longitude_deg>0</longitude_deg>
      <elevation>0</elevation>
      <heading_deg>0</heading_deg>
    </spherical_coordinates>
    <state world_name='default'>
      <sim_time>70 744000000</sim_time>
      <real_time>71 599577391</real_time>
      <wall_time>1660336621 540749207</wall_time>
      <iterations>70744</iterations>
      <model name='centauri6dof'>
        <pose>-2 1.5 0.900001 3e-06 6e-06 0</pose>
        <scale>1 1 1</scale>
        <link name='base_link'>
          <pose>-2.00004 1.41823 0.869622 3e-06 6e-06 0</pose>
          <velocity>-0.000481 -2e-05 -0.000278 -0.00284 -0.01114 0.000577</velocity>
          <acceleration>-0.006202 -0.036559 -0.045813 -0.172224 -1.20264 0.038094</acceleration>
          <wrench>-0.032532 -0.19176 -0.240294 0 -0 0</wrench>
        </link>
        <link name='gear1'>
          <pose>-2.00578 1.38411 1.60233 1.86773 0.937625 0.398467</pose>
          <velocity>-2.77496 -41.3942 -4.56036 -2.55543 -0.388453 -0.208827</velocity>
          <acceleration>-6665.16 -1539.95 -3974.94 0 -0 0</acceleration>
          <wrench>-32.516 -7.51265 -19.3917 0 -0 0</wrench>
        </link>
        <link name='gear2'>
          <pose>-1.9827 1.39008 1.59172 -0.882008 0.779178 2.76162</pose>
          <velocity>1.01538 -43.354 2.29919 -0.133156 1.19791 1.47407</velocity>
          <acceleration>255.581 -1565.48 8658.24 0 -0 0</acceleration>
          <wrench>1.27872 -7.8324 43.3188 0 -0 0</wrench>
        </link>
        <link name='link1'>
          <pose>-2.00005 1.41824 0.935622 1.57079 3e-05 -0.452088</pose>
          <velocity>0.032154 0.003474 -0.000437 0.011818 -0.077147 0.177211</velocity>
          <acceleration>2.97977 2.11853 -0.060279 -1.02713 -0.1139 -0.208892</acceleration>
          <wrench>6.00539 4.26966 -0.121485 0 -0 0</wrench>
        </link>
        <link name='link2'>
          <pose>-2.00007 1.41815 1.08286 1.57094 0.092664 -1.56225</pose>
          <velocity>0.046841 -0.014455 0.356519 -1.54396 0.968178 0.202372</velocity>
          <acceleration>7.88113 -78.7087 0.612831 -1.19135 0.571504 0.776624</acceleration>
          <wrench>15.4746 -154.544 1.20329 0 -0 0</wrench>
        </link>
        <link name='link3'>
          <pose>-1.99648 1.398 1.30608 1.57082 0.063496 -1.56224</pose>
          <velocity>0.413745 -20.7326 -0.817695 0.962356 0.225243 0.196984</velocity>
          <acceleration>30.5915 142.186 4.59987 2.01829 1.21133 -2.331</acceleration>
          <wrench>36.1132 167.851 5.43014 0 -0 0</wrench>
        </link>
        <link name='link4'>
          <pose>-1.99677 1.39086 1.43435 0.071859 0.010053 0.013381</pose>
          <velocity>0.745549 -28.9729 -1.12036 -3.03722 -1.49999 2.13158</velocity>
          <acceleration>87.1423 -19.7247 -24.5006 2.93325 -0.897751 2.67349</acceleration>
          <wrench>56.876 -12.8739 -15.991 0 -0 0</wrench>
        </link>
        <link name='link5'>
          <pose>-1.99751 1.38468 1.52982 1.56026 0.082392 -1.54464</pose>
          <velocity>0.950621 -35.1987 -1.45271 2.19001 -0.572433 -3.04326</velocity>
          <acceleration>80.1814 832.787 -42.389 -1.5918 0.05058 2.71096</acceleration>
          <wrench>13.1618 136.702 -6.95815 0 -0 0</wrench>
        </link>
        <link name='link6'>
          <pose>-2.0045 1.38709 1.57156 0.304739 0.393828 0.336845</pose>
          <velocity>0.403696 -40.2922 -2.04585 -1.39344 0.432188 2.21711</velocity>
          <acceleration>-2391.24 -1894.62 643.059 -1.34773 -0.363195 2.3818</acceleration>
          <wrench>-154.039 -122.048 41.4246 0 -0 0</wrench>
        </link>
        <link name='pinza1'>
          <pose>-2.02759 1.375 1.63471 1.78314 0.606813 0.278952</pose>
          <velocity>-2.42915 -41.087 -4.20752 -2.56134 -0.42769 -0.202191</velocity>
          <acceleration>-6976.59 -1733.68 -4163.1 0 -0 0</acceleration>
          <wrench>-73.1921 -18.1882 -43.6755 0 -0 0</wrench>
        </link>
        <link name='pinza2'>
          <pose>-1.95632 1.37955 1.61986 -0.882147 0.779019 2.76143</pose>
          <velocity>1.01087 -42.9957 2.46465 0.017074 1.31459 1.37632</velocity>
          <acceleration>-638.203 -1530.4 8683.01 0 -0 0</acceleration>
          <wrench>-6.69546 -16.0556 91.0943 0 -0 0</wrench>
        </link>
        <link name='pivot1'>
          <pose>-1.95402 1.39602 1.59419 -0.802326 0.76528 -0.405834</pose>
          <velocity>7.77036 -41.286 -2.76671 -3.11163 -1.10622 -1.62997</velocity>
          <acceleration>20817.8 -5684.86 -4612.44 0 -0 0</acceleration>
          <wrench>34.7713 -9.49525 -7.70402 0 -0 0</wrench>
        </link>
        <link name='pivot2'>
          <pose>-1.97646 1.37901 1.60745 -0.03852 -0.035763 -1.62358</pose>
          <velocity>-2.75901 -41.9271 -0.514336 2.85411 0.420695 -2.38029</velocity>
          <acceleration>-6599.08 -1743.43 5288.67 0 -0 0</acceleration>
          <wrench>-11.0222 -2.91201 8.83351 0 -0 0</wrench>
        </link>
      </model>
      <model name='ground_plane'>
        <pose>0 0 0 0 -0 0</pose>
        <scale>1 1 1</scale>
        <link name='link'>
          <pose>0 0 0 0 -0 0</pose>
          <velocity>0 0 0 0 -0 0</velocity>
          <acceleration>0 0 0 0 -0 0</acceleration>
          <wrench>0 0 0 0 -0 0</wrench>
        </link>
      </model>
      <light name='sun'>
        <pose>0 0 10 0 -0 0</pose>
      </light>
    </state>
    <gui fullscreen='0'>
      <camera name='user_camera'>
        <pose>4.20667 0.643306 2.11425 0 0.339642 3.03618</pose>
        <view_controller>orbit</view_controller>
        <projection_type>perspective</projection_type>
      </camera>
    </gui>
    <model name='centauri6dof'>
      <joint name='joint_fixed' type='fixed'>
        <pose relative_to='__model__'>-3.9e-05 -0.081765 -0.030378 0 -0 0</pose>
        <parent>world</parent>
        <child>base_link</child>
      </joint>
      <link name='base_link'>
        <pose relative_to='joint_fixed'>0 0 0 0 -0 0</pose>
        <inertial>
          <pose>0.024465 -0.056958 -0.011371 0 -0 0</pose>
          <mass>5.24516</mass>
          <inertia>
            <ixx>0.0914651</ixx>
            <ixy>-0.00732087</ixy>
            <ixz>-0.00536943</ixz>
            <iyy>0.0989479</iyy>
            <iyz>-0.00555333</iyz>
            <izz>0.175837</izz>
          </inertia>
        </inertial>
        <collision name='base_link_collision'>
          <pose>0 0 0 0 -0 0</pose>
          <geometry>
            <mesh>
              <scale>1 1 1</scale>
              <uri>model://centauri_2022/meshes/base_link.STL</uri>
            </mesh>
          </geometry>
          <max_contacts>10</max_contacts>
          <surface>
            <contact>
              <ode/>
            </contact>
            <bounce/>
            <friction>
              <torsional>
                <ode/>
              </torsional>
              <ode/>
            </friction>
          </surface>
        </collision>
        <collision name='base_link_fixed_joint_lump__link0_collision_1'>
          <pose>0 0 0 0 -0 0</pose>
          <geometry>
            <mesh>
              <scale>1 1 1</scale>
              <uri>model://centauri_2022/meshes/link0.STL</uri>
            </mesh>
          </geometry>
          <max_contacts>10</max_contacts>
          <surface>
            <contact>
              <ode/>
            </contact>
            <bounce/>
            <friction>
              <torsional>
                <ode/>
              </torsional>
              <ode/>
            </friction>
          </surface>
        </collision>
        <visual name='base_link_visual'>
          <pose>0 0 0 0 -0 0</pose>
          <geometry>
            <mesh>
              <scale>1 1 1</scale>
              <uri>model://centauri_2022/meshes/base_link.STL</uri>
            </mesh>
          </geometry>
        </visual>
        <visual name='base_link_fixed_joint_lump__link0_visual_1'>
          <pose>0 0 0 0 -0 0</pose>
          <geometry>
            <mesh>
              <scale>1 1 1</scale>
              <uri>model://centauri_2022/meshes/link0.STL</uri>
            </mesh>
          </geometry>
        </visual>
        <self_collide>0</self_collide>
        <enable_wind>0</enable_wind>
        <kinematic>0</kinematic>
      </link>
      <joint name='joint1' type='revolute'>
        <pose relative_to='base_link'>0 0 0.066 1.5708 0 -0.452227</pose>
        <parent>base_link</parent>
        <child>link1</child>
        <axis>
          <xyz>0 1 0</xyz>
          <limit>
            <lower>-1.5707</lower>
            <upper>1.5707</upper>
            <effort>300</effort>
            <velocity>1</velocity>
          </limit>
          <dynamics>
            <spring_reference>0</spring_reference>
            <spring_stiffness>0</spring_stiffness>
          </dynamics>
        </axis>
      </joint>
      <link name='link1'>
        <pose relative_to='joint1'>0 0 0 0 -0 0</pose>
        <inertial>
          <pose>3.8e-05 0.074178 -9e-05 0 -0 0</pose>
          <mass>2.01539</mass>
          <inertia>
            <ixx>0.00353227</ixx>
            <ixy>9.69664e-06</ixy>
            <ixz>0.00297172</ixz>
            <iyy>0.00746342</iyy>
            <iyz>-1.00853e-06</iyz>
            <izz>0.00804646</izz>
          </inertia>
        </inertial>
        <collision name='link1_collision'>
          <pose>0 0 0 0 -0 0</pose>
          <geometry>
            <mesh>
              <scale>1 1 1</scale>
              <uri>model://centauri_2022/meshes/link1.STL</uri>
            </mesh>
          </geometry>
          <max_contacts>10</max_contacts>
          <surface>
            <contact>
              <ode/>
            </contact>
            <bounce/>
            <friction>
              <torsional>
                <ode/>
              </torsional>
              <ode/>
            </friction>
          </surface>
        </collision>
        <visual name='link1_visual'>
          <pose>0 0 0 0 -0 0</pose>
          <geometry>
            <mesh>
              <scale>1 1 1</scale>
              <uri>model://centauri_2022/meshes/link1.STL</uri>
            </mesh>
          </geometry>
        </visual>
        <self_collide>0</self_collide>
        <enable_wind>0</enable_wind>
        <kinematic>0</kinematic>
      </link>
      <joint name='joint2' type='revolute'>
        <pose relative_to='link1'>0 0.1455 0 0 -1.11019 0</pose>
        <parent>link1</parent>
        <child>link2</child>
        <axis>
          <xyz>0 0 -1</xyz>
          <limit>
            <lower>-1.5707</lower>
            <upper>1.5707</upper>
            <effort>5</effort>
            <velocity>1</velocity>
          </limit>
          <dynamics>
            <spring_reference>0</spring_reference>
            <spring_stiffness>0</spring_stiffness>
          </dynamics>
        </axis>
      </joint>
      <link name='link2'>
        <pose relative_to='joint2'>0 0 0 0 -0 0</pose>
        <inertial>
          <pose>0.000198 0.082039 0.001009 0 -0 0</pose>
          <mass>1.9635</mass>
          <inertia>
            <ixx>0.012176</ixx>
            <ixy>-2.6636e-05</ixy>
            <ixz>-4.6349e-07</ixz>
            <iyy>0.00060347</iyy>
            <iyz>-0.00013766</iyz>
            <izz>0.011573</izz>
          </inertia>
        </inertial>
        <collision name='link2_collision'>
          <pose>0 0 0 0 -0 0</pose>
          <geometry>
            <mesh>
              <scale>1 1 1</scale>
              <uri>model://centauri_2022/meshes/link2.STL</uri>
            </mesh>
          </geometry>
          <max_contacts>10</max_contacts>
          <surface>
            <contact>
              <ode/>
            </contact>
            <bounce/>
            <friction>
              <torsional>
                <ode/>
              </torsional>
              <ode/>
            </friction>
          </surface>
        </collision>
        <visual name='link2_visual'>
          <pose>0 0 0 0 -0 0</pose>
          <geometry>
            <mesh>
              <scale>1 1 1</scale>
              <uri>model://centauri_2022/meshes/link2.STL</uri>
            </mesh>
          </geometry>
        </visual>
        <self_collide>0</self_collide>
        <enable_wind>0</enable_wind>
        <kinematic>0</kinematic>
      </link>
      <joint name='joint3' type='revolute'>
        <pose relative_to='link2'>0.000684 0.221123 -0.003496 0 -0 0</pose>
        <parent>link2</parent>
        <child>link3</child>
        <axis>
          <xyz>0 0 -1</xyz>
          <limit>
            <lower>-1.5707</lower>
            <upper>1.5707</upper>
            <effort>5</effort>
            <velocity>1</velocity>
          </limit>
          <dynamics>
            <spring_reference>0</spring_reference>
            <spring_stiffness>0</spring_stiffness>
          </dynamics>
        </axis>
      </joint>
      <link name='link3'>
        <pose relative_to='joint3'>0 0 0 0 -0 0</pose>
        <inertial>
          <pose>0.000626 0.048649 0.000676 0 -0 0</pose>
          <mass>1.1805</mass>
          <inertia>
            <ixx>0.000542025</ixx>
            <ixy>-1.139e-05</ixy>
            <ixz>-2.51651e-07</ixz>
            <iyy>0.000253427</iyy>
            <iyz>-1.51961e-05</iyz>
            <izz>0.000289499</izz>
          </inertia>
        </inertial>
        <collision name='link3_collision'>
          <pose>0 0 0 0 -0 0</pose>
          <geometry>
            <mesh>
              <scale>1 1 1</scale>
              <uri>model://centauri_2022/meshes/link3.STL</uri>
            </mesh>
          </geometry>
          <max_contacts>10</max_contacts>
          <surface>
            <contact>
              <ode/>
            </contact>
            <bounce/>
            <friction>
              <torsional>
                <ode/>
              </torsional>
              <ode/>
            </friction>
          </surface>
        </collision>
        <visual name='link3_visual'>
          <pose>0 0 0 0 -0 0</pose>
          <geometry>
            <mesh>
              <scale>1 1 1</scale>
              <uri>model://centauri_2022/meshes/link3.STL</uri>
            </mesh>
          </geometry>
        </visual>
        <self_collide>0</self_collide>
        <enable_wind>0</enable_wind>
        <kinematic>0</kinematic>
      </link>
      <joint name='joint4' type='revolute'>
        <pose relative_to='link3'>0.00044 0.1275 0 -1.5708 1.5624 -0.003449</pose>
        <parent>link3</parent>
        <child>link4</child>
        <axis>
          <xyz>0 0 1</xyz>
          <limit>
            <lower>-1.5707</lower>
            <upper>1.5707</upper>
            <effort>5</effort>
            <velocity>1</velocity>
          </limit>
          <dynamics>
            <spring_reference>0</spring_reference>
            <spring_stiffness>0</spring_stiffness>
          </dynamics>
        </axis>
      </joint>
      <link name='link4'>
        <pose relative_to='joint4'>0 0 0 0 -0 0</pose>
        <inertial>
          <pose>0.011293 -0.000225 0.045445 0 -0 0</pose>
          <mass>0.65268</mass>
          <inertia>
            <ixx>4.43e-05</ixx>
            <ixy>-1.9291e-06</ixy>
            <ixz>5.7823e-05</ixz>
            <iyy>0.00012329</iyy>
            <iyz>1.4718e-06</iyz>
            <izz>7.9091e-05</izz>
          </inertia>
        </inertial>
        <collision name='link4_collision'>
          <pose>0 0 0 0 -0 0</pose>
          <geometry>
            <mesh>
              <scale>1 1 1</scale>
              <uri>model://centauri_2022/meshes/link4.STL</uri>
            </mesh>
          </geometry>
          <max_contacts>10</max_contacts>
          <surface>
            <contact>
              <ode/>
            </contact>
            <bounce/>
            <friction>
              <torsional>
                <ode/>
              </torsional>
              <ode/>
            </friction>
          </surface>
        </collision>
        <visual name='link4_visual'>
          <pose>0 0 0 0 -0 0</pose>
          <geometry>
            <mesh>
              <scale>1 1 1</scale>
              <uri>model://centauri_2022/meshes/link4.STL</uri>
            </mesh>
          </geometry>
        </visual>
        <self_collide>0</self_collide>
        <enable_wind>0</enable_wind>
        <kinematic>0</kinematic>
      </link>
      <joint name='joint5' type='revolute'>
        <pose relative_to='link4'>-0.001 0 0.095 1.5708 -0.017142 -1.56911</pose>
        <parent>link4</parent>
        <child>link5</child>
        <axis>
          <xyz>0 0 -1</xyz>
          <limit>
            <lower>-1.5707</lower>
            <upper>1.5707</upper>
            <effort>5</effort>
            <velocity>1</velocity>
          </limit>
          <dynamics>
            <spring_reference>0</spring_reference>
            <spring_stiffness>0</spring_stiffness>
          </dynamics>
        </axis>
      </joint>
      <link name='link5'>
        <pose relative_to='joint5'>0 0 0 0 -0 0</pose>
        <inertial>
          <pose>0.000134 0.004274 -0.000312 0 -0 0</pose>
          <mass>0.16415</mass>
          <inertia>
            <ixx>3.7602e-05</ixx>
            <ixy>-5.5077e-07</ixy>
            <ixz>9.5822e-09</ixz>
            <iyy>2.0116e-05</iyy>
            <iyz>3.0426e-07</iyz>
            <izz>1.7521e-05</izz>
          </inertia>
        </inertial>
        <collision name='link5_collision'>
          <pose>0 0 0 0 -0 0</pose>
          <geometry>
            <mesh>
              <scale>1 1 1</scale>
              <uri>model://centauri_2022/meshes/link5.STL</uri>
            </mesh>
          </geometry>
          <max_contacts>10</max_contacts>
          <surface>
            <contact>
              <ode/>
            </contact>
            <bounce/>
            <friction>
              <torsional>
                <ode/>
              </torsional>
              <ode/>
            </friction>
          </surface>
        </collision>
        <visual name='link5_visual'>
          <pose>0 0 0 0 -0 0</pose>
          <geometry>
            <mesh>
              <scale>1 1 1</scale>
              <uri>model://centauri_2022/meshes/link5.STL</uri>
            </mesh>
          </geometry>
        </visual>
        <self_collide>0</self_collide>
        <enable_wind>0</enable_wind>
        <kinematic>0</kinematic>
      </link>
      <joint name='joint6' type='revolute'>
        <pose relative_to='link5'>0.00129 0.04098 0 0 1.5707 1.5393</pose>
        <parent>link5</parent>
        <child>link6</child>
        <axis>
          <xyz>5.3e-05 0 1</xyz>
          <limit>
            <lower>-1.5707</lower>
            <upper>1.5707</upper>
            <effort>5</effort>
            <velocity>1</velocity>
          </limit>
          <dynamics>
            <spring_reference>0</spring_reference>
            <spring_stiffness>0</spring_stiffness>
          </dynamics>
        </axis>
      </joint>
      <link name='link6'>
        <pose relative_to='joint6'>0 0 0 0 -0 0</pose>
        <inertial>
          <pose>-0.002831 -0.014417 0.020832 0 -0 0</pose>
          <mass>0.064418</mass>
          <inertia>
            <ixx>1.6924e-05</ixx>
            <ixy>-3.1692e-06</ixy>
            <ixz>6.6553e-07</ixz>
            <iyy>1.3455e-06</iyy>
            <iyz>2.861e-06</iyz>
            <izz>1.7067e-05</izz>
          </inertia>
        </inertial>
        <collision name='link6_collision'>
          <pose>0 0 0 0 -0 0</pose>
          <geometry>
            <mesh>
              <scale>1 1 1</scale>
              <uri>model://centauri_2022/meshes/link6.STL</uri>
            </mesh>
          </geometry>
          <max_contacts>10</max_contacts>
          <surface>
            <contact>
              <ode/>
            </contact>
            <bounce/>
            <friction>
              <torsional>
                <ode/>
              </torsional>
              <ode/>
            </friction>
          </surface>
        </collision>
        <visual name='link6_visual'>
          <pose>0 0 0 0 -0 0</pose>
          <geometry>
            <mesh>
              <scale>1 1 1</scale>
              <uri>model://centauri_2022/meshes/link6.STL</uri>
            </mesh>
          </geometry>
        </visual>
        <self_collide>0</self_collide>
        <enable_wind>0</enable_wind>
        <kinematic>0</kinematic>
      </link>
      <joint name='joint_gear1' type='revolute'>
        <pose relative_to='link6'>-0.014169 -0.002052 0.024001 1.57079 0.38395 -0.067301</pose>
        <parent>link6</parent>
        <child>gear1</child>
        <axis>
          <xyz>0 0 1</xyz>
          <limit>
            <lower>-0.95</lower>
            <upper>0</upper>
            <effort>5</effort>
            <velocity>1</velocity>
          </limit>
          <dynamics>
            <spring_reference>0</spring_reference>
            <spring_stiffness>0</spring_stiffness>
          </dynamics>
        </axis>
      </joint>
      <link name='gear1'>
        <pose relative_to='joint_gear1'>0 0 0 0 -0 0</pose>
        <inertial>
          <pose>-0.006595 -0.000395 -0.003 0 -0 0</pose>
          <mass>0.0048785</mass>
          <inertia>
            <ixx>0</ixx>
            <ixy>0</ixy>
            <ixz>0</ixz>
            <iyy>0</iyy>
            <iyz>0</iyz>
            <izz>0</izz>
          </inertia>
        </inertial>
        <collision name='gear1_collision'>
          <pose>0 0 0 0 -0 0</pose>
          <geometry>
            <mesh>
              <scale>1 1 1</scale>
              <uri>model://centauri_2022/meshes/gear1.STL</uri>
            </mesh>
          </geometry>
          <max_contacts>10</max_contacts>
          <surface>
            <contact>
              <ode/>
            </contact>
            <bounce/>
            <friction>
              <torsional>
                <ode/>
              </torsional>
              <ode/>
            </friction>
          </surface>
        </collision>
        <visual name='gear1_visual'>
          <pose>0 0 0 0 -0 0</pose>
          <geometry>
            <mesh>
              <scale>1 1 1</scale>
              <uri>model://centauri_2022/meshes/gear1.STL</uri>
            </mesh>
          </geometry>
        </visual>
        <self_collide>0</self_collide>
        <enable_wind>0</enable_wind>
        <kinematic>0</kinematic>
      </link>
      <joint name='joint_pinza1' type='revolute'>
        <pose relative_to='gear1'>-0.04 0 0 0 -0 0</pose>
        <parent>gear1</parent>
        <child>pinza1</child>
        <axis>
          <xyz>0 0 1</xyz>
          <limit>
            <effort>5</effort>
            <velocity>1</velocity>
            <lower>-1e+16</lower>
            <upper>1e+16</upper>
          </limit>
          <dynamics>
            <spring_reference>0</spring_reference>
            <spring_stiffness>0</spring_stiffness>
          </dynamics>
        </axis>
      </joint>
      <link name='pinza1'>
        <pose relative_to='joint_pinza1'>0 0 0 0 -0 0</pose>
        <inertial>
          <pose>-0.004107 0.028872 -0.003252 0 -0 0</pose>
          <mass>0.0104911</mass>
          <inertia>
            <ixx>0</ixx>
            <ixy>0</ixy>
            <ixz>0</ixz>
            <iyy>0</iyy>
            <iyz>0</iyz>
            <izz>0</izz>
          </inertia>
        </inertial>
        <collision name='pinza1_collision'>
          <pose>0 0 0 0 -0 0</pose>
          <geometry>
            <mesh>
              <scale>1 1 1</scale>
              <uri>model://centauri_2022/meshes/pinza1.STL</uri>
            </mesh>
          </geometry>
          <max_contacts>10</max_contacts>
          <surface>
            <contact>
              <ode/>
            </contact>
            <bounce/>
            <friction>
              <torsional>
                <ode/>
              </torsional>
              <ode/>
            </friction>
          </surface>
        </collision>
        <visual name='pinza1_visual'>
          <pose>0 0 0 0 -0 0</pose>
          <geometry>
            <mesh>
              <scale>1 1 1</scale>
              <uri>model://centauri_2022/meshes/pinza1.STL</uri>
            </mesh>
          </geometry>
        </visual>
        <self_collide>0</self_collide>
        <enable_wind>0</enable_wind>
        <kinematic>0</kinematic>
      </link>
      <joint name='joint_gear2' type='revolute'>
        <pose relative_to='link6'>0.013768 -0.003935 0.023999 -1.57079 0.400772 3.0743</pose>
        <parent>link6</parent>
        <child>gear2</child>
        <axis>
          <xyz>0 0 1</xyz>
          <limit>
            <lower>0</lower>
            <upper>0.95</upper>
            <effort>5</effort>
            <velocity>1</velocity>
          </limit>
          <dynamics>
            <spring_reference>0</spring_reference>
            <spring_stiffness>0</spring_stiffness>
          </dynamics>
        </axis>
      </joint>
      <link name='gear2'>
        <pose relative_to='joint_gear2'>0 0 0 0 -0 0</pose>
        <inertial>
          <pose>-0.006453 0.000407 -0.003 0 -0 0</pose>
          <mass>0.00500319</mass>
          <inertia>
            <ixx>0</ixx>
            <ixy>0</ixy>
            <ixz>0</ixz>
            <iyy>0</iyy>
            <iyz>0</iyz>
            <izz>0</izz>
          </inertia>
        </inertial>
        <collision name='gear2_collision'>
          <pose>0 0 0 0 -0 0</pose>
          <geometry>
            <mesh>
              <scale>1 1 1</scale>
              <uri>model://centauri_2022/meshes/gear2.STL</uri>
            </mesh>
          </geometry>
          <max_contacts>10</max_contacts>
          <surface>
            <contact>
              <ode/>
            </contact>
            <bounce/>
            <friction>
              <torsional>
                <ode/>
              </torsional>
              <ode/>
            </friction>
          </surface>
        </collision>
        <visual name='gear2_visual'>
          <pose>0 0 0 0 -0 0</pose>
          <geometry>
            <mesh>
              <scale>1 1 1</scale>
              <uri>model://centauri_2022/meshes/gear2.STL</uri>
            </mesh>
          </geometry>
        </visual>
        <self_collide>0</self_collide>
        <enable_wind>0</enable_wind>
        <kinematic>0</kinematic>
      </link>
      <joint name='joint_pinza2' type='revolute'>
        <pose relative_to='gear2'>-0.04 0 0 0 -0 0</pose>
        <parent>gear2</parent>
        <child>pinza2</child>
        <axis>
          <xyz>0 0 1</xyz>
          <limit>
            <lower>-1.5</lower>
            <upper>0</upper>
            <effort>5</effort>
            <velocity>1</velocity>
          </limit>
          <dynamics>
            <spring_reference>0</spring_reference>
            <spring_stiffness>0</spring_stiffness>
          </dynamics>
        </axis>
      </joint>
      <link name='pinza2'>
        <pose relative_to='joint_pinza2'>0 0 0 0 -0 0</pose>
        <inertial>
          <pose>-0.004595 -0.028799 -0.003252 0 -0 0</pose>
          <mass>0.0104911</mass>
          <inertia>
            <ixx>0</ixx>
            <ixy>0</ixy>
            <ixz>0</ixz>
            <iyy>0</iyy>
            <iyz>0</iyz>
            <izz>0</izz>
          </inertia>
        </inertial>
        <collision name='pinza2_collision'>
          <pose>0 0 0 0 -0 0</pose>
          <geometry>
            <mesh>
              <scale>1 1 1</scale>
              <uri>model://centauri_2022/meshes/pinza2.STL</uri>
            </mesh>
          </geometry>
          <max_contacts>10</max_contacts>
          <surface>
            <contact>
              <ode/>
            </contact>
            <bounce/>
            <friction>
              <torsional>
                <ode/>
              </torsional>
              <ode/>
            </friction>
          </surface>
        </collision>
        <visual name='pinza2_visual'>
          <pose>0 0 0 0 -0 0</pose>
          <geometry>
            <mesh>
              <scale>1 1 1</scale>
              <uri>model://centauri_2022/meshes/pinza2.STL</uri>
            </mesh>
          </geometry>
        </visual>
        <self_collide>0</self_collide>
        <enable_wind>0</enable_wind>
        <kinematic>0</kinematic>
      </link>
      <joint name='joint_pivot1' type='revolute'>
        <pose relative_to='link6'>-0.007184 -0.002522 0.044 1.57079 0.38395 -0.067301</pose>
        <parent>link6</parent>
        <child>pivot1</child>
        <axis>
          <xyz>0 0 1</xyz>
          <limit>
            <lower>-1.5707</lower>
            <upper>1.5707</upper>
            <effort>5</effort>
            <velocity>1</velocity>
          </limit>
          <dynamics>
            <spring_reference>0</spring_reference>
            <spring_stiffness>0</spring_stiffness>
          </dynamics>
        </axis>
      </joint>
      <link name='pivot1'>
        <pose relative_to='joint_pivot1'>0 0 0 0 -0 0</pose>
        <inertial>
          <pose>-0.02 0 -0.003 0 -0 0</pose>
          <mass>0.00167027</mass>
          <inertia>
            <ixx>0</ixx>
            <ixy>0</ixy>
            <ixz>0</ixz>
            <iyy>0</iyy>
            <iyz>0</iyz>
            <izz>0</izz>
          </inertia>
        </inertial>
        <collision name='pivot1_collision'>
          <pose>0 0 0 0 -0 0</pose>
          <geometry>
            <mesh>
              <scale>1 1 1</scale>
              <uri>model://centauri_2022/meshes/pivot1.STL</uri>
            </mesh>
          </geometry>
          <max_contacts>10</max_contacts>
          <surface>
            <contact>
              <ode/>
            </contact>
            <bounce/>
            <friction>
              <torsional>
                <ode/>
              </torsional>
              <ode/>
            </friction>
          </surface>
        </collision>
        <visual name='pivot1_visual'>
          <pose>0 0 0 0 -0 0</pose>
          <geometry>
            <mesh>
              <scale>1 1 1</scale>
              <uri>model://centauri_2022/meshes/pivot1.STL</uri>
            </mesh>
          </geometry>
        </visual>
        <self_collide>0</self_collide>
        <enable_wind>0</enable_wind>
        <kinematic>0</kinematic>
      </link>
      <joint name='joint_pivot2' type='revolute'>
        <pose relative_to='link6'>0.006785 -0.003464 0.044 -1.57079 0.400772 3.0743</pose>
        <parent>link6</parent>
        <child>pivot2</child>
        <axis>
          <xyz>0 0 1</xyz>
          <limit>
            <lower>-1.5707</lower>
            <upper>1.5707</upper>
            <effort>5</effort>
            <velocity>1</velocity>
          </limit>
          <dynamics>
            <spring_reference>0</spring_reference>
            <spring_stiffness>0</spring_stiffness>
          </dynamics>
        </axis>
      </joint>
      <link name='pivot2'>
        <pose relative_to='joint_pivot2'>0 0 0 0 -0 0</pose>
        <inertial>
          <pose>-0.02 0 -0.003 0 -0 0</pose>
          <mass>0.00167027</mass>
          <inertia>
            <ixx>0</ixx>
            <ixy>0</ixy>
            <ixz>0</ixz>
            <iyy>0</iyy>
            <iyz>0</iyz>
            <izz>0</izz>
          </inertia>
        </inertial>
        <collision name='pivot2_collision'>
          <pose>0 0 0 0 -0 0</pose>
          <geometry>
            <mesh>
              <scale>1 1 1</scale>
              <uri>model://centauri_2022/meshes/pivot2.STL</uri>
            </mesh>
          </geometry>
          <max_contacts>10</max_contacts>
          <surface>
            <contact>
              <ode/>
            </contact>
            <bounce/>
            <friction>
              <torsional>
                <ode/>
              </torsional>
              <ode/>
            </friction>
          </surface>
        </collision>
        <visual name='pivot2_visual'>
          <pose>0 0 0 0 -0 0</pose>
          <geometry>
            <mesh>
              <scale>1 1 1</scale>
              <uri>model://centauri_2022/meshes/pivot2.STL</uri>
            </mesh>
          </geometry>
        </visual>
        <self_collide>0</self_collide>
        <enable_wind>0</enable_wind>
        <kinematic>0</kinematic>
      </link>
      <static>0</static>
      <plugin name='gazebo_ros2_control' filename='libgazebo_ros2_control.so'>
        <robot_sim_type>gazebo_ros2_control/GazeboSystem</robot_sim_type>
        <parameters>/home/federico/dev_ws/src/centauri_2022/config/joint_centauri_controller.yaml</parameters>
      </plugin>
      <pose>-2 1.5 0.9 0 -0 0</pose>
    </model>
  </world>
</sdf>
